Workbook

Sheet Hoja1
A2: Longitud Taco | B2: CANT. RETENEDORES (GREDAD) | C2: N° PERA | D2: TIPO APD | E2: ESTADO TIRO | F2: TIRO CON AGUA | G2: TIRO NEGATIVO ó POSITIVO | H2: Metros Cama ANFO | I2: JEFE TURNO JEJ | J2: ENCARGADO SEGUIMIENTO | K2: MINA | L2: TURNO | M2: ARAÑA EN CEBO | N2: Diámetro de Carguío [pulg] | O2: Cantidad de Cartuchos | P2: Tipo Retendor | Q2: Nivel | R2: Bloque | S2: Explosivo | T2: Fase | U2: Lianza | V2: Arañas Inferior | W2: Sacos | X2: Gredas | Y2: Arañas Superir | Z2: Cama de Explosivo | AB2: Temperatura °C | AC2: 15 | AD2: 35 | AE2: °C
A3: 1 | B3: Sí | C3: 1 | D3: 150 | E3: Sano | F3: Seco | G3: Negativo | H3: 0 | I3: Alexis Salinas | J3: Alex muñoz | K3: Andesita | L3: A | M3: Si | N3: 2 | O3: 0 | P3: Greda | Q3: NP | R3: B-2 | S3: AnFo | T3: 1 | U3: Sí | V3: 1 | W3: 1 | X3: 1 | Y3: 1 | Z3: 0 | AB3: PH | AC3: 4.3 | AD3: 4.6
A4: 1.5 | B4: No | C4: 2 | D4: 225 | E4: Perdido | F4: Agua | G4: Positivo | H4: 0.5 | I4: Hector Flores | J4: Luis Salinas | K4: Diablo Regimiento | L4: B | M4: No | N4: 3 | O4: 1 | P4: Cartón | Q4: UCL | R4: B-6 | S4: Emulsión | T4: 1.6666667 | U4: No | V4: 2 | W4: 2 | X4: 2 | Y4: 2 | Z4: 0.5 | AB4: Viscosidad | AC4: > | AD4: 1500000 | AE4: cp
A5: 2 | C5: 3 | D5: 250 | E5: Roto | F5: Agua Dinamica | H5: 1 | I5: Nicolas Escudero | J5: Carlos castro | K5: Diamante | L5: Especial | N5: 3.5 | O5: 2 | P5: Bolsa | Q5: Panel 2 | R5: Ext Fw | T5: 2 | V5: 3 | W5: 3 | X5: 3 | Y5: 3 | Z5: 1 | AB5: Concentración L30 | AC5: 3.23 | AD5: %
A6: 2.5 | C6: 4 | D6: WebGen | E6: Agrietado | H6: 1.5 | I6: Raimundo Silva | J6: Hector Flores | K6: Esmeralda | O6: 3 | P6: Araña | R6: DHz | T6: 3 | V6: 4 | X6: 4 | Y6: 4 | Z6: 1.5 | AB6: Inyección L30 | AC6: <= | AD6: 1.667 | AE6: %
A7: 3 | C7: 5 | D7: Especial | E7: Molido | H7: 2 | I7: Victor Hernández | J7: Nicolás Valdovinos | K7: NNM | O7: 4 | T7: 4 | V7: 5 | Y7: 5 | Z7: 2 | AB7: Calibración Bomba (+/- 1%) | AC7: 20 | AD7: =AC7*0.01 -> 0.2 | AE7: kg | AF7: Calibración Bomba | AG7: 27.2 | AH7: 0.3 | AI7: kg
A8: 3.5 | C8: 6 | E8: Cortado | H8: 2.5 | J8: Victor Hernández | K8: Pacífico Superior | O8: 5 | V8: 6 | Z8: 2.5 | AB8: Tempo de Gasificación | AC8: 30 | AD8: 60 | AE8: min
A9: 4 | C9: 7 | E9: Corto | H9: 3 | K9: Pilar Norte | O9: 6 | V9: 7 | Z9: 3 | AB9: Densidad final | AC9: 1.15 | AD9: =AC9*0.05 -> 0.0575 | AE9: ton/m3
A10: 4.5 | C10: 8 | E10: Estrecho | H10: 3.5 | K10: Reservas Norte | O10: 7 | V10: 8 | Z10: 3.5 | AB10: Densidad lineal en 3" | AC10: 5.2 | AD10: 0.04 | AE10: kg/m | AF10: Densidad lineal en 3.3" | AG10: 7.1 | AH10: 0.04 | AI10: v
A11: 5 | C11: 9 | E11: s/i | H11: 4 | K11: TT8 | O11: 8 | V11: 9 | Z11: 4
A12: 5.5 | C12: 10 | H12: 4.5 | O12: 9 | V12: 10 | Z12: 4.5 | AD12: kg/m | AE12: Factor respecto a calibración de bomba
A13: 6 | C13: 11 | H13: 5 | O13: 10 | Z13: 5 | AB13: 3" | AC13: =PI()*(3*25.4/2000)^2 -> 0.0045603673 | AD13: =AC13*$AC$9*1000 -> 5.2444224 | AE13: =($AC$7-$AD$7)/$AD$13 -> 3.7754396 | AF13: =($AC$7+$AD$7)/$AD$13 -> 3.8517111
A14: 6.5 | C14: 12 | H14: 5.5 | O14: 11 | Z14: 5.5 | AB14: 3.5" | AC14: =PI()*(3.5*25.4/2000)^2 -> 0.0062071666 | AD14: =AC14*$AC$9*1000 -> 7.1382416
A15: 7 | C15: 13 | H15: 6 | O15: 12 | Z15: 6 | AE15: =AE13*$AD$14 -> 26.95 | AF15: =AF13*$AD$14 -> 27.494444
A16: 7.5 | C16: 14 | H16: 6.5 | O16: 13 | Z16: 6.5 | AE16: 27.2
A17: 8 | C17: 15 | H17: 7 | O17: 14 | Z17: 7 | AE17: =(AE16-AE15)/AE16 -> 0.0091911765 | AF17: =(AF15-AE16)/AE16 -> 0.010825163
A18: 8.5 | C18: 16 | H18: 7.5 | O18: 15 | Z18: 7.5
A19: 9 | C19: 17 | H19: 8 | O19: 16 | Z19: 8
A20: 9.5 | C20: 18 | H20: 8.5 | O20: 17 | Z20: 8.5
A21: 10 | C21: 19 | H21: 9 | O21: 18 | Z21: 9
A22: 10.5 | C22: 20 | H22: 9.5 | O22: 19 | Z22: 9.5 | AC22: =AC9-AD9 -> 1.0925 | AD22: =AC9+AD9 -> 1.2075
A23: 11 | H23: 10 | O23: 20 | Z23: 10
A24: 11.5 | H24: 10.5 | O24: 21
A25: 12 | H25: 11 | O25: 22
A26: 12.5 | H26: 11.5 | O26: 23
A27: 13 | H27: 12 | O27: 24
A28: 13.5 | H28: 12.5 | O28: 25
A29: 14 | H29: 13
A30: 14.5 | H30: 13.5
A31: 15 | H31: 14
A32: 15.5 | H32: 14.5
A33: 16 | H33: 15
A34: 16.5 | H34: 15.5
A35: 17 | H35: 16
A36: 17.5 | H36: 16.5
A37: 18 | H37: 17
A38: 18.5 | H38: 17.5
A39: 19 | H39: 18
A40: 19.5 | H40: 18.5
... A43: 21 | H43: 20
...

Sheet JEJ
F2: HOJA DE TERRENO SEGUIMIENTO AL CARGUIO
F3: J. E. J. INGENIERÍA S. A. CONTRATO N° 4600026097 | AE3: Adherencia
F4: SERVICIO QA/QC OPERACIONES DE PERFORACIÓN Y TRONADURA | AE4: Cumplimiento | AF4: Porcentaje
B5: Fecha | D5: 21/09/26 | F5: H Llegada JeJ a Postura | H5: 0.75 | M5: Núm. Zanja | O5: 8 | Q5: Temperatura de Matríz | S5: =IF(R5="","",IF(R5>=Hoja1!AC2,IF(R5<=Hoja1!AD2,"Ok","X"),"X")) | T5: Hora Inicio Amarre | V5: Hora Fin Amarre | Y5: Total Tiempo Amarre | AA5: =IF(X5="","",IF(U5="","",X5-U5)) | AE5: Lianza | AF5: =IF(COUNTIF(M16:M83,"Roto")=0,"",COUNTIF(AD16:AD83,"Sí")/COUNTIF(M16:M83,"Roto"))
B6: Tuno | D6: B | F6: H Salida JeJ de Postura | H6: 0.85416667 | M6: Calles Zanja | O6: 41 | P6: 43 | Q6: PH de la Matríz | S6: =IF(R6="","",IF(R6>=Hoja1!AC3,IF(R6<=Hoja1!AD3,"Ok","X"),"X")) | T6: Pérdida Operacional Durante el Carguío | AC6: TIEMPO | AE6: Arañas Inferiores | AF6: =IF(COUNTIF(M16:M83,"Roto")=0,"",COUNTIF(AF16:AF83,"ok")/COUNTIF(M16:M83,"Roto"))
B7: Mina | D7: Esmeralda | F7: H Llegada PyT a Postura | Q7: Viscocidad Emulsión | S7: =IF(R7="","",IF(R7>=Hoja1!AD4,"Ok","X")) | T7: Sin VoD por motivo a que tiro con tiempo 0 se encontraba corto con 3,5 mts de su totalidad. | AE7: Sacos | AF7: =IF(COUNTIF(M16:M83,"Roto")=0,"",COUNTIF(AH16:AH83,"ok")/COUNTIF(M16:M83,"Roto"))
B8: Nivel | D8: NP | F8: H Inicio Carguío | M8: Fase | O8: 3 | Q8: Concentración L30 | S8: =IF(R8="","",IF(R8=Hoja1!AC5,"Ok","")) | AE8: Gredas | AF8: =IF(COUNTIF(M16:M83,"Roto")=0,"",COUNTIF(AJ16:AJ83,"ok")/COUNTIF(M16:M83,"Roto"))
B9: Bloque | D9: B-2 | F9: H Fin Carguío | M9: Calle UCL | Q9: Inyección L30 | S9: =IF(R9="","",IF(R9<=Hoja1!AD6,"Ok","")) | AE9: Arañas Superiores | AF9: =IF(COUNTIF(M16:M83,"Roto")=0,"",COUNTIF(AL16:AL83,"ok")/COUNTIF(M16:M83,"Roto"))
B10: ID Tronadura | D10: =IF(O5>0,CONCATENATE("Z",O5," ","C",O6,"/",P6," ","F",O8),IF(O9>0,CONCATENATE("C",O9," ","P",O10," a ",O11,"neg"),"")) -> Z8 C41/43 F3 | F10: H Salida PyT de Postura | M10: Parada Inicial | Q10: Calibración Bomba | S10: =IF(R10="","",IF(L13=3,IF(R10>=(Hoja1!AC7-Hoja1!AD7),IF(R10<=(Hoja1!AC7+Hoja1!AD7),"Ok","X"),"X"),IF(R10>=(Hoja1!AG7-Hoja1!AH7),IF(R10<=(Hoja1!AG7+Hoja1!AH7),"Ok","X"),"X"))) | AE10: Cama | AF10: =IF(COUNTIF(M16:M83,"Roto")=0,"",COUNTIF(AN16:AN83,"ok")/COUNTIF(M16:M83,"Roto"))
B11: Supervisor JeJ | D11: Hector Flores | F11: Tiempo en Postura | H11: =IF(L10="","",IF(L7="","",L10-L7)) | M11: Parada Final (neg) | Q11: Tiempo de Gasificación [min] | S11: =IF(R11="","",IF(R11>=Hoja1!AC8,IF(R11<=Hoja1!AD8,"Ok","X"),"X")) | T11: Pérdida Operacional Durante el Amarre | AC11: TIEMPO
B12: Encargado Seguimiento JeJ | D12: Luis Salinas | F12: Tiempo en Carguío | H12: =IF(L9="","",IF(L8="","",L9-L8)) | M12: Ubicación de Geófono | O12: Z49 HW C43 | Q12: Rango de Densidad Final en Vaso [kg/m3] | S12: =IF(R12="","",IF(R12>=(Hoja1!AC9-Hoja1!AD9),IF(R12<=(Hoja1!AC9+Hoja1!AD9),"Ok","X"),"X"))
B13: Supervisor DET | D13: Andrés Bugeño | F13: Diámetro Tiros [pulg] | H13: 3 | M13: Altura Geófono [m] | O13: 2 | Q13: Rango Densidad Lineal Programada [kg/m] | R13: =IF(L13=3,Hoja1!AC10-Hoja1!AD10,IF(L13=3.5,Hoja1!AG10-Hoja1!AH10,"")) | S13: =IF(L13=3,Hoja1!AC10+Hoja1!AD10,IF(L13=3.5,Hoja1!AG10+Hoja1!AH10,"")) | AD13: PROTOCOLO PARA TIROS ROTOS
B14: Responsable Carguio DET | D14: Nicolas Flores | F14: Tiro con VoD | M14: Distancia al Geófono [m] | O14: 10 | Q14: Densidad Lineal Lograda [kg/m] | R14: =IF(SUM(L16:L83)=0,"",SUM(P16:P83)/(SUM(L16:L83)-0.032*(COUNT(R16:R83,U16:U83)+SUM(T16:T83,W16:W83)))) -> 4.0540725 | S14: =IF(R14="","",IF(R14>=R13,IF(R14<=S13,"Ok","Alto"),"Bajo")) -> Bajo | AD14: INSTALA LIANZA | AE14: INSTALA ARAÑAS INFERIORES | AG14: INSTALA SACOS | AI14: INSTALA GREDAS | AK14: INSTALA ARAÑAS SUPERIOR | AM14: CAMA DE EXPLOSIVO | AO14: DETALLE DE LA CARGA DE COLUMNA
B15: PARADA | C15: TIRO | D15: LONG. DISEÑO [M] | E15: TACO DISEÑO [M] | F15: LARGO MOMENTO CARGAR [M] | G15: TACO REAL [M] | H15: TACO EN FONDO EN TIROS LARGOS | I15: NÚM DE GREDAS | J15: TACO EN FONDO REAL | K15: NÚM GREDAS REAL | L15: METROS CARGADOS [M] | M15: ESTADO TIRO | N15: TIRO CON AGUA | O15: TIRO NEGATIVO / POSITIVO | P15: EMUSLION CARGADA [kg] | Q15: CAMA EXPLOSIVO [M] | R15: CEBO SUPERIOR | S15: ARAÑA EN CEBO SUPERIOR | T15: CANT. CARTUCHOS | U15: CEBO INFERIOR | V15: ARAÑA EN CEBO INFERIOR | W15: CANT. CARTUCHOS | X15: ARAÑA EMULSIÓN | Y15: USO RETENEDOR | Z15: RETARDO por DISEÑO [ms] | AA15: RETARDO REAL [ms] | AB15: ORDEN SECUENCIA | AC15: TIEMPO CARGUÍO DEL TIRO | AD15: CUMPLE | AE15: NÚMERO | AF15: CUMPLE | AG15: NÚMERO | AH15: CUMPLE | AI15: NÚMERO | AJ15: CUMPLE | AK15: NÚMERO | AL15: CUMPLE | AM15: METROS | AN15: CUMPLE | AO15: LONG. AL TERMINAR CAMA | AP15: LONG. 1ER CEBO | AQ15: LONG. AL TERMINAR CARGA INTERMEDIA | AR15: LONG. 2DO CEBO | AS15: LONG. CARGA INFERIOR | AT15: LONG. RETENEDOR | AU15: LONG TACO DE GREDA
A16: 1 | B16: 15 | C16: 1 | D16: 18 | E16: 3 | F16: 15 | G16: 3 | H16: =IF(OR(F16=0,D16=0),"",IF(F16-D16>0,F16-D16,"")) | I16: =IF(H16="","",INT(5*(F16-D16))) | L16: =F16-G16 -> 12 | M16: Sano | N16: Seco | O16: Positivo | P16: 68 | R16: 150 | S16: Si | T16: 1 | U16: 150 | V16: Si | W16: 1 | X16: Sí | Y16: Araña | AF16: =IF(AE16="","",IF(AE16>=10,"ok","X")) | AH16: =IF(AG16="","",IF(AG16>=3,"ok","X")) | AJ16: =IF(AI16="","",IF(AI16>=4,"ok","X")) | AL16: =IF(AK16="","",IF(AK16>=5,"ok","X")) | AN16: {=IF(AM16="","",IF((F16-G16)>=4,IF(AM16>=3,"ok","X"),IF(AM16>=1,IF(AM16<=2,"ok","X"),X)))} | AO16: 14 | AP16: 14,3 | AQ16: 8 | AR16: 8.3 | AT16: 3
A17: 2 | C17: 2 | D17: 20 | E17: 5 | F17: 18 | G17: 5 | H17: =IF(OR(F17=0,D17=0),"",IF(F17-D17>0,F17-D17,"")) | I17: =IF(H17="","",INT(5*(F17-D17))) | L17: =F17-G17 -> 13 | M17: Sano | N17: Seco | O17: Positivo | P17: 72.3 | R17: 150 | S17: Si | T17: 1 | U17: 150 | V17: Si | W17: 1 | X17: Sí | Y17: Araña | AF17: =IF(AE17="","",IF(AE17>=10,"ok","X")) | AH17: =IF(AG17="","",IF(AG17>=3,"ok","X")) | AJ17: =IF(AI17="","",IF(AI17>=4,"ok","X")) | AL17: =IF(AK17="","",IF(AK17>=5,"ok","X")) | AN17: {=IF(AM17="","",IF((F17-G17)>=4,IF(AM17>=3,"ok","X"),IF(AM17>=1,IF(AM17<=2,"ok","X"),X)))} | AO17: 17 | AP17: 17.5 | AQ17: 10 | AR17: 10.4 | AT17: 5
A18: 3 | C18: 3 | D18: 30 | E18: 3 | F18: 19.5 | G18: 3 | H18: =IF(OR(F18=0,D18=0),"",IF(F18-D18>0,F18-D18,"")) | I18: =IF(H18="","",INT(5*(F18-D18))) | L18: =F18-G18 -> 16.5 | M18: Sano | N18: Seco | O18: Positivo | P18: 88.4 | R18: 150 | S18: Si | T18: 1 | X18: Sí | Y18: Araña | AF18: =IF(AE18="","",IF(AE18>=10,"ok","X")) | AH18: =IF(AG18="","",IF(AG18>=3,"ok","X")) | AJ18: =IF(AI18="","",IF(AI18>=4,"ok","X")) | AL18: =IF(AK18="","",IF(AK18>=5,"ok","X")) | AN18: {=IF(AM18="","",IF((F18-G18)>=4,IF(AM18>=3,"ok","X"),IF(AM18>=1,IF(AM18<=2,"ok","X"),X)))} | AO18: 18.5 | AP18: 18.6 | AQ18: 9.5 | AT18: 3
A19: 4 | C19: 4 | D19: 30 | E19: 2 | F19: 29.5 | G19: 2 | H19: =IF(OR(F19=0,D19=0),"",IF(F19-D19>0,F19-D19,"")) | I19: =IF(H19="","",INT(5*(F19-D19))) | L19: =F19-G19 -> 27.5 | M19: Sano | N19: Seco | O19: Positivo | P19: 150.2 | R19: 150 | S19: Si | T19: 1 | U19: 150 | V19: Si | W19: 2 | X19: Sí | Y19: Araña | AF19: =IF(AE19="","",IF(AE19>=10,"ok","X")) | AH19: =IF(AG19="","",IF(AG19>=3,"ok","X")) | AJ19: =IF(AI19="","",IF(AI19>=4,"ok","X")) | AL19: =IF(AK19="","",IF(AK19>=5,"ok","X")) | AN19: {=IF(AM19="","",IF((F19-G19)>=4,IF(AM19>=3,"ok","X"),IF(AM19>=1,IF(AM19<=2,"ok","X"),X)))} | AO19: 28.5 | AP19: 28.8 | AQ19: 19.5 | AR19: 19.7 | AS19: 10.3 | AT19: 2
A20: 5 | C20: 5 | D20: 30 | E20: 3 | F20: 30.1 | G20: 3 | L20: =F20-G20 -> 27.1 | M20: Sano | N20: Seco | O20: Positivo | P20: 140 | R20: 150 | S20: Si | T20: 1 | U20: 150 | V20: Si | W20: 2 | X20: Sí | Y20: Araña | AF20: =IF(AE20="","",IF(AE20>=10,"ok","X")) | AH20: =IF(AG20="","",IF(AG20>=3,"ok","X")) | AJ20: =IF(AI20="","",IF(AI20>=4,"ok","X")) | AL20: =IF(AK20="","",IF(AK20>=5,"ok","X")) | AN20: {=IF(AM20="","",IF((F20-G20)>=4,IF(AM20>=3,"ok","X"),IF(AM20>=1,IF(AM20<=2,"ok","X"),X)))} | AO20: 29 | AP20: 29.2 | AQ20: 20 | AR20: 20.2 | AS20: 11.1 | AT20: 3
A21: 6 | C21: 6 | D21: 25 | E21: 3 | F21: 24.1 | G21: 3 | H21: =IF(OR(F21=0,D21=0),"",IF(F21-D21>0,F21-D21,"")) | I21: =IF(H21="","",INT(5*(F21-D21))) | L21: =F21-G21 -> 21.1 | M21: Sano | N21: Seco | O21: Positivo | P21: 114,2 | R21: 150 | S21: Si | T21: 1 | U21: 150 | V21: Si | W21: 2 | X21: Sí | Y21: Araña | AF21: =IF(AE21="","",IF(AE21>=10,"ok","X")) | AH21: =IF(AG21="","",IF(AG21>=3,"ok","X")) | AJ21: =IF(AI21="","",IF(AI21>=4,"ok","X")) | AL21: =IF(AK21="","",IF(AK21>=5,"ok","X")) | AN21: {=IF(AM21="","",IF((F21-G21)>=4,IF(AM21>=3,"ok","X"),IF(AM21>=1,IF(AM21<=2,"ok","X"),X)))} | AO21: 23 | AP21: 22.1 | AQ21: 15 | AR21: 15,2 | AS21: 6,2 | AT21: 3
A22: 7 | C22: 7 | D22: 30 | E22: 3 | F22: 20 | G22: 3 | H22: =IF(OR(F22=0,D22=0),"",IF(F22-D22>0,F22-D22,"")) | I22: =IF(H22="","",INT(5*(F22-D22))) | L22: =F22-G22 -> 17 | M22: Sano | N22: Seco | O22: Positivo | P22: 91,6 | R22: 150 | S22: Si | T22: 1 | U22: 150 | V22: Si | W22: 1 | X22: Sí | Y22: Araña | AF22: =IF(AE22="","",IF(AE22>=10,"ok","X")) | AH22: =IF(AG22="","",IF(AG22>=3,"ok","X")) | AJ22: =IF(AI22="","",IF(AI22>=4,"ok","X")) | AL22: =IF(AK22="","",IF(AK22>=5,"ok","X")) | AN22: {=IF(AM22="","",IF((F22-G22)>=4,IF(AM22>=3,"ok","X"),IF(AM22>=1,IF(AM22<=2,"ok","X"),X)))} | AO22: 19 | AP22: 19,3 | AQ22: 12 | AR22: 12,3 | AT22: 3
A23: 8 | C23: 8 | D23: 17 | E23: 2 | H23: =IF(OR(F23=0,D23=0),"",IF(F23-D23>0,F23-D23,"")) | I23: =IF(H23="","",INT(5*(F23-D23))) | L23: =F23-G23 -> 0 | AF23: =IF(AE23="","",IF(AE23>=10,"ok","X")) | AH23: =IF(AG23="","",IF(AG23>=3,"ok","X")) | AJ23: =IF(AI23="","",IF(AI23>=4,"ok","X")) | AL23: =IF(AK23="","",IF(AK23>=5,"ok","X")) | AN23: {=IF(AM23="","",IF((F23-G23)>=4,IF(AM23>=3,"ok","X"),IF(AM23>=1,IF(AM23<=2,"ok","X"),X)))}
A24: 9 | C24: 9 | D24: 16 | E24: 3 | H24: =IF(OR(F24=0,D24=0),"",IF(F24-D24>0,F24-D24,"")) | I24: =IF(H24="","",INT(5*(F24-D24))) | L24: =F24-G24 -> 0 | AF24: =IF(AE24="","",IF(AE24>=10,"ok","X")) | AH24: =IF(AG24="","",IF(AG24>=3,"ok","X")) | AJ24: =IF(AI24="","",IF(AI24>=4,"ok","X")) | AL24: =IF(AK24="","",IF(AK24>=5,"ok","X")) | AN24: {=IF(AM24="","",IF((F24-G24)>=4,IF(AM24>=3,"ok","X"),IF(AM24>=1,IF(AM24<=2,"ok","X"),X)))}
A25: 10 | C25: 10 | D25: 17.5 | E25: 5 | H25: =IF(OR(F25=0,D25=0),"",IF(F25-D25>0,F25-D25,"")) | I25: =IF(H25="","",INT(5*(F25-D25))) | L25: =F25-G25 -> 0 | AF25: =IF(AE25="","",IF(AE25>=10,"ok","X")) | AH25: =IF(AG25="","",IF(AG25>=3,"ok","X")) | AJ25: =IF(AI25="","",IF(AI25>=4,"ok","X")) | AL25: =IF(AK25="","",IF(AK25>=5,"ok","X")) | AN25: {=IF(AM25="","",IF((F25-G25)>=4,IF(AM25>=3,"ok","X"),IF(AM25>=1,IF(AM25<=2,"ok","X"),X)))}
A26: 11 | C26: 11 | D26: 15 | E26: 3 | H26: =IF(OR(F26=0,D26=0),"",IF(F26-D26>0,F26-D26,"")) | I26: =IF(H26="","",INT(5*(F26-D26))) | L26: =F26-G26 -> 0 | AF26: =IF(AE26="","",IF(AE26>=10,"ok","X")) | AH26: =IF(AG26="","",IF(AG26>=3,"ok","X")) | AJ26: =IF(AI26="","",IF(AI26>=4,"ok","X")) | AL26: =IF(AK26="","",IF(AK26>=5,"ok","X")) | AN26: {=IF(AM26="","",IF((F26-G26)>=4,IF(AM26>=3,"ok","X"),IF(AM26>=1,IF(AM26<=2,"ok","X"),X)))}
A27: 12 | B27: 16 | C27: 1 | D27: 18 | E27: 1 | F27: 14.4 | G27: 1 | H27: =IF(OR(F27=0,D27=0),"",IF(F27-D27>0,F27-D27,"")) | I27: =IF(H27="","",INT(5*(F27-D27))) | L27: =F27-G27 -> 13.4 | M27: Sano | N27: Seco | O27: Positivo | P27: 75.2 | R27: 150 | S27: Si | T27: 1 | U27: 150 | V27: Si | W27: 1 | X27: Sí | Y27: Araña | AF27: =IF(AE27="","",IF(AE27>=10,"ok","X")) | AH27: =IF(AG27="","",IF(AG27>=3,"ok","X")) | AJ27: =IF(AI27="","",IF(AI27>=4,"ok","X")) | AL27: =IF(AK27="","",IF(AK27>=5,"ok","X")) | AN27: {=IF(AM27="","",IF((F27-G27)>=4,IF(AM27>=3,"ok","X"),IF(AM27>=1,IF(AM27<=2,"ok","X"),X)))} | AO27: 13,4 | AP27: 13,7 | AQ27: 7 | AR27: 7,5 | AT27: 1
A28: 13 | C28: 2 | D28: 22 | E28: 5 | H28: =IF(OR(F28=0,D28=0),"",IF(F28-D28>0,F28-D28,"")) | I28: =IF(H28="","",INT(5*(F28-D28))) | L28: =F28-G28 -> 0 | AF28: =IF(AE28="","",IF(AE28>=10,"ok","X")) | AH28: =IF(AG28="","",IF(AG28>=3,"ok","X")) | AJ28: =IF(AI28="","",IF(AI28>=4,"ok","X")) | AL28: =IF(AK28="","",IF(AK28>=5,"ok","X")) | AN28: {=IF(AM28="","",IF((F28-G28)>=4,IF(AM28>=3,"ok","X"),IF(AM28>=1,IF(AM28<=2,"ok","X"),X)))}
A29: 14 | C29: 3 | D29: 30 | E29: 2 | H29: =IF(OR(F29=0,D29=0),"",IF(F29-D29>0,F29-D29,"")) | I29: =IF(H29="","",INT(5*(F29-D29))) | L29: =F29-G29 -> 0 | AF29: =IF(AE29="","",IF(AE29>=10,"ok","X")) | AH29: =IF(AG29="","",IF(AG29>=3,"ok","X")) | AJ29: =IF(AI29="","",IF(AI29>=4,"ok","X")) | AL29: =IF(AK29="","",IF(AK29>=5,"ok","X")) | AN29: {=IF(AM29="","",IF((F29-G29)>=4,IF(AM29>=3,"ok","X"),IF(AM29>=1,IF(AM29<=2,"ok","X"),X)))}
A30: 15 | C30: 4 | D30: 30 | E30: 1 | H30: =IF(OR(F30=0,D30=0),"",IF(F30-D30>0,F30-D30,"")) | I30: =IF(H30="","",INT(5*(F30-D30))) | L30: =F30-G30 -> 0 | AF30: =IF(AE30="","",IF(AE30>=10,"ok","X")) | AH30: =IF(AG30="","",IF(AG30>=3,"ok","X")) | AJ30: =IF(AI30="","",IF(AI30>=4,"ok","X")) | AL30: =IF(AK30="","",IF(AK30>=5,"ok","X")) | AN30: {=IF(AM30="","",IF((F30-G30)>=4,IF(AM30>=3,"ok","X"),IF(AM30>=1,IF(AM30<=2,"ok","X"),X)))}
A31: 16 | C31: 5 | D31: 30 | E31: 2 | H31: =IF(OR(F31=0,D31=0),"",IF(F31-D31>0,F31-D31,"")) | I31: =IF(H31="","",INT(5*(F31-D31))) | L31: =F31-G31 -> 0 | AF31: =IF(AE31="","",IF(AE31>=10,"ok","X")) | AH31: =IF(AG31="","",IF(AG31>=3,"ok","X")) | AJ31: =IF(AI31="","",IF(AI31>=4,"ok","X")) | AL31: =IF(AK31="","",IF(AK31>=5,"ok","X")) | AN31: {=IF(AM31="","",IF((F31-G31)>=4,IF(AM31>=3,"ok","X"),IF(AM31>=1,IF(AM31<=2,"ok","X"),X)))}
A32: 17 | C32: 6 | D32: 24 | E32: 1 | H32: =IF(OR(F32=0,D32=0),"",IF(F32-D32>0,F32-D32,"")) | I32: =IF(H32="","",INT(5*(F32-D32))) | L32: =F32-G32 -> 0 | AF32: =IF(AE32="","",IF(AE32>=10,"ok","X")) | AH32: =IF(AG32="","",IF(AG32>=3,"ok","X")) | AJ32: =IF(AI32="","",IF(AI32>=4,"ok","X")) | AL32: =IF(AK32="","",IF(AK32>=5,"ok","X")) | AN32: {=IF(AM32="","",IF((F32-G32)>=4,IF(AM32>=3,"ok","X"),IF(AM32>=1,IF(AM32<=2,"ok","X"),X)))}
A33: 18 | C33: 7 | D33: 20 | E33: 2 | H33: =IF(OR(F33=0,D33=0),"",IF(F33-D33>0,F33-D33,"")) | I33: =IF(H33="","",INT(5*(F33-D33))) | L33: =F33-G33 -> 0 | AF33: =IF(AE33="","",IF(AE33>=10,"ok","X")) | AH33: =IF(AG33="","",IF(AG33>=3,"ok","X")) | AJ33: =IF(AI33="","",IF(AI33>=4,"ok","X")) | AL33: =IF(AK33="","",IF(AK33>=5,"ok","X")) | AN33: {=IF(AM33="","",IF((F33-G33)>=4,IF(AM33>=3,"ok","X"),IF(AM33>=1,IF(AM33<=2,"ok","X"),X)))}
A34: 19 | C34: 8 | D34: 17.5 | E34: 1 | H34: =IF(OR(F34=0,D34=0),"",IF(F34-D34>0,F34-D34,"")) | I34: =IF(H34="","",INT(5*(F34-D34))) | L34: =F34-G34 -> 0 | AF34: =IF(AE34="","",IF(AE34>=10,"ok","X")) | AH34: =IF(AG34="","",IF(AG34>=3,"ok","X")) | AJ34: =IF(AI34="","",IF(AI34>=4,"ok","X")) | AL34: =IF(AK34="","",IF(AK34>=5,"ok","X")) | AN34: {=IF(AM34="","",IF((F34-G34)>=4,IF(AM34>=3,"ok","X"),IF(AM34>=1,IF(AM34<=2,"ok","X"),X)))}
A35: 20 | C35: 9 | D35: 16.5 | E35: 2 | H35: =IF(OR(F35=0,D35=0),"",IF(F35-D35>0,F35-D35,"")) | I35: =IF(H35="","",INT(5*(F35-D35))) | L35: =F35-G35 -> 0 | AF35: =IF(AE35="","",IF(AE35>=10,"ok","X")) | AH35: =IF(AG35="","",IF(AG35>=3,"ok","X")) | AJ35: =IF(AI35="","",IF(AI35>=4,"ok","X")) | AL35: =IF(AK35="","",IF(AK35>=5,"ok","X")) | AN35: {=IF(AM35="","",IF((F35-G35)>=4,IF(AM35>=3,"ok","X"),IF(AM35>=1,IF(AM35<=2,"ok","X"),X)))}
A36: 21 | C36: 10 | D36: 18 | E36: 5 | H36: =IF(OR(F36=0,D36=0),"",IF(F36-D36>0,F36-D36,"")) | I36: =IF(H36="","",INT(5*(F36-D36))) | L36: =F36-G36 -> 0 | AF36: =IF(AE36="","",IF(AE36>=10,"ok","X")) | AH36: =IF(AG36="","",IF(AG36>=3,"ok","X")) | AJ36: =IF(AI36="","",IF(AI36>=4,"ok","X")) | AL36: =IF(AK36="","",IF(AK36>=5,"ok","X")) | AN36: {=IF(AM36="","",IF((F36-G36)>=4,IF(AM36>=3,"ok","X"),IF(AM36>=1,IF(AM36<=2,"ok","X"),X)))}
A37: 22 | C37: 11 | D37: 15 | E37: 1 | H37: =IF(OR(F37=0,D37=0),"",IF(F37-D37>0,F37-D37,"")) | I37: =IF(H37="","",INT(5*(F37-D37))) | L37: =F37-G37 -> 0 | AF37: =IF(AE37="","",IF(AE37>=10,"ok","X")) | AH37: =IF(AG37="","",IF(AG37>=3,"ok","X")) | AJ37: =IF(AI37="","",IF(AI37>=4,"ok","X")) | AL37: =IF(AK37="","",IF(AK37>=5,"ok","X")) | AN37: {=IF(AM37="","",IF((F37-G37)>=4,IF(AM37>=3,"ok","X"),IF(AM37>=1,IF(AM37<=2,"ok","X"),X)))}
A38: 23 | H38: =IF(OR(F38=0,D38=0),"",IF(F38-D38>0,F38-D38,"")) | I38: =IF(H38="","",INT(5*(F38-D38))) | L38: =F38-G38 -> 0 | AF38: =IF(AE38="","",IF(AE38>=10,"ok","X")) | AH38: =IF(AG38="","",IF(AG38>=3,"ok","X")) | AJ38: =IF(AI38="","",IF(AI38>=4,"ok","X")) | AL38: =IF(AK38="","",IF(AK38>=5,"ok","X")) | AN38: {=IF(AM38="","",IF((F38-G38)>=4,IF(AM38>=3,"ok","X"),IF(AM38>=1,IF(AM38<=2,"ok","X"),X)))}
A39: 24 | H39: =IF(OR(F39=0,D39=0),"",IF(F39-D39>0,F39-D39,"")) | I39: =IF(H39="","",INT(5*(F39-D39))) | L39: =F39-G39 -> 0 | AF39: =IF(AE39="","",IF(AE39>=10,"ok","X")) | AH39: =IF(AG39="","",IF(AG39>=3,"ok","X")) | AJ39: =IF(AI39="","",IF(AI39>=4,"ok","X")) | AL39: =IF(AK39="","",IF(AK39>=5,"ok","X")) | AN39: {=IF(AM39="","",IF((F39-G39)>=4,IF(AM39>=3,"ok","X"),IF(AM39>=1,IF(AM39<=2,"ok","X"),X)))}
A40: 25 | H40: =IF(OR(F40=0,D40=0),"",IF(F40-D40>0,F40-D40,"")) | I40: =IF(H40="","",INT(5*(F40-D40))) | L40: =F40-G40 -> 0 | AF40: =IF(AE40="","",IF(AE40>=10,"ok","X")) | AH40: =IF(AG40="","",IF(AG40>=3,"ok","X")) | AJ40: =IF(AI40="","",IF(AI40>=4,"ok","X")) | AL40: =IF(AK40="","",IF(AK40>=5,"ok","X")) | AN40: {=IF(AM40="","",IF((F40-G40)>=4,IF(AM40>=3,"ok","X"),IF(AM40>=1,IF(AM40<=2,"ok","X"),X)))}
A41: 26 | H41: =IF(OR(F41=0,D41=0),"",IF(F41-D41>0,F41-D41,"")) | I41: =IF(H41="","",INT(5*(F41-D41))) | L41: =F41-G41 -> 0 | AF41: =IF(AE41="","",IF(AE41>=10,"ok","X")) | AH41: =IF(AG41="","",IF(AG41>=3,"ok","X")) | AJ41: =IF(AI41="","",IF(AI41>=4,"ok","X")) | AL41: =IF(AK41="","",IF(AK41>=5,"ok","X")) | AN41: {=IF(AM41="","",IF((F41-G41)>=4,IF(AM41>=3,"ok","X"),IF(AM41>=1,IF(AM41<=2,"ok","X"),X)))}
...
